Workbook

Sheet Worksheet
A1: BRAC University
A2: Advising Section Confirmation Status
A3: Session:SUMMER 2026
A4: Academic Degree Undergraduate
A5: Course: CSE220 - 12
A7: Student Id | B7: Name | C7: Program | D7: Email | E7: Phone | F7: Course Code | G7: Section | H7: Section Type | I7: Course Faculty | J7: Confirmation Status
A8: 22301333 | B8: Nazmus Sakib | C8: CSE | D8: nazmus.sakib10@g.bracu.ac.bd | E8: 01316314221 | F8: CSE220 | G8: 12 | H8: OTHER | I8: SWG | J8: Yes
A9: 23301549 | B9: Navid Mahmood | C9: CSE | D9: navid.mahmood@g.bracu.ac.bd | E9: 01976500243 | F9: CSE220 | G9: 12 | H9: OTHER | I9: SWG | J9: Yes
A10: 23301673 | B10: Mahiba Tasnim | C10: CSE | D10: mahiba.tasnim@g.bracu.ac.bd | E10: 01947137857 | F10: CSE220 | G10: 12 | H10: OTHER | I10: SWG | J10: Yes
A11: 23201533 | B11: Nusrat Jahan Arpa | C11: CSE | D11: nusrat.jahan.arpa@g.bracu.ac.bd | E11: 01759215094 | F11: CSE220 | G11: 12 | H11: OTHER | I11: SWG | J11: Yes
A12: 24101194 | B12: Ohi Ahmed | C12: CSE | D12: ohi.ahmed@g.bracu.ac.bd | E12: 01886695425 | F12: CSE220 | G12: 12 | H12: OTHER | I12: SWG | J12: Yes
A13: 24101253 | B13: Md. Asiful Islam | C13: CSE | D13: md.asiful.islam3@g.bracu.ac.bd | E13: 01810519940 | F13: CSE220 | G13: 12 | H13: OTHER | I13: SWG | J13: Yes
A14: 24301317 | B14: Ashmita Deb Nath | C14: CSE | D14: ashmita.deb.nath@g.bracu.ac.bd | E14: 01819494680 | F14: CSE220 | G14: 12 | H14: OTHER | I14: SWG | J14: Yes
A15: 24301488 | B15: Obontika Rashid Prethula | C15: CSE | D15: obontika.rashid.prethula@g.bracu.ac.bd | E15: 01994782492 | F15: CSE220 | G15: 12 | H15: OTHER | I15: SWG | J15: Yes
A16: 24341037 | B16: Abrar Yaman Reza | C16: CS | D16: abrar.yaman.reza@g.bracu.ac.bd | E16: 01975376502 | F16: CSE220 | G16: 12 | H16: OTHER | I16: SWG | J16: Yes
A17: 24201116 | B17: Zarif Tausif Ahmed Nafi | C17: CSE | D17: zarif.tausif.ahmed@g.bracu.ac.bd | E17: 01314661974 | F17: CSE220 | G17: 12 | H17: OTHER | I17: SWG | J17: Yes
A18: 22101447 | B18: Showrav Sutradhar | C18: CSE | D18: showrav.sutradhar@g.bracu.ac.bd | E18: 01834246042 | F18: CSE220 | G18: 12 | H18: OTHER | I18: SWG | J18: Yes
... A47: 24321192 | B47: Shadman Ahmed | C47: CSE | D47: shadman.ahmed2@g.bracu.ac.bd | E47: +8801339303903 | F47: CSE220 | G47: 12 | H47: OTHER | I47: SWG | J47: Yes

Sheet Quiz Marks
B2: QUIZ MARKS
A5: SL | B5: Student Id | C5: Name | D5: Quiz-01 (20 Marks) | E5: Quiz-02 (20 Marks) | F5: Quiz-03 (15 Marks) | G5: Quiz-04 (20 Marks) | I5: Quiz-01 | J5: Quiz-02 | K5: Quiz-03 | L5: Quiz-04 | M5: Total 15%
A6: 1 | B6: 22301333 | C6: Nazmus Sakib | D6: 17 | E6: 17 | F6: 14 | G6: 3 | I6: =D6*(15/20) -> 12.75 | J6: =E6*(15/20) -> 12.75 | K6: =F6 -> 14 | L6: =G6*(15/20) -> 2.25 | M6: =(LARGE(I6:L6,1)+LARGE(I6:L6,2)+LARGE(I6:L6,3))/3 -> 13.166667
A7: =A6+1 -> 2 | B7: 23301549 | C7: Navid Mahmood | D7: 6 | E7: 14 | F7: 11 | G7: 13 | I7: =D7*(15/20) -> 4.5 | J7: =E7*(15/20) -> 10.5 | K7: =F7 -> 11 | L7: =G7*(15/20) -> 9.75 | M7: =(LARGE(I7:L7,1)+LARGE(I7:L7,2)+LARGE(I7:L7,3))/3 -> 10.416667
A8: =A7+1 -> 3 | B8: 23301673 | C8: Mahiba Tasnim | F8: 5 | G8: 7 | I8: =D8*(15/20) -> 0 | J8: =E8*(15/20) -> 0 | K8: =F8 -> 5 | L8: =G8*(15/20) -> 5.25 | M8: =(LARGE(I8:L8,1)+LARGE(I8:L8,2)+LARGE(I8:L8,3))/3 -> 3.4166667
A9: =A8+1 -> 4 | B9: 23201533 | C9: Nusrat Jahan Arpa | D9: 17 | E9: 18 | F9: 14 | G9: 7 | I9: =D9*(15/20) -> 12.75 | J9: =E9*(15/20) -> 13.5 | K9: =F9 -> 14 | L9: =G9*(15/20) -> 5.25 | M9: =(LARGE(I9:L9,1)+LARGE(I9:L9,2)+LARGE(I9:L9,3))/3 -> 13.416667
A10: =A9+1 -> 5 | B10: 24101194 | C10: Ohi Ahmed | E10: 14 | F10: 12 | G10: 15 | I10: =D10*(15/20) -> 0 | J10: =E10*(15/20) -> 10.5 | K10: =F10 -> 12 | L10: =G10*(15/20) -> 11.25 | M10: =(LARGE(I10:L10,1)+LARGE(I10:L10,2)+LARGE(I10:L10,3))/3 -> 11.25
A11: =A10+1 -> 6 | B11: 24101253 | C11: Md. Asiful Islam | D11: 18 | E11: 13 | F11: 13 | G11: 7 | I11: =D11*(15/20) -> 13.5 | J11: =E11*(15/20) -> 9.75 | K11: =F11 -> 13 | L11: =G11*(15/20) -> 5.25 | M11: =(LARGE(I11:L11,1)+LARGE(I11:L11,2)+LARGE(I11:L11,3))/3 -> 12.083333
A12: =A11+1 -> 7 | B12: 24301317 | C12: Ashmita Deb Nath | D12: 14 | E12: 13 | F12: 10 | G12: 2 | I12: =D12*(15/20) -> 10.5 | J12: =E12*(15/20) -> 9.75 | K12: =F12 -> 10 | L12: =G12*(15/20) -> 1.5 | M12: =(LARGE(I12:L12,1)+LARGE(I12:L12,2)+LARGE(I12:L12,3))/3 -> 10.083333
A13: =A12+1 -> 8 | B13: 24301488 | C13: Obontika Rashid Prethula | D13: 12 | E13: 10 | F13: 12 | G13: 8 | I13: =D13*(15/20) -> 9 | J13: =E13*(15/20) -> 7.5 | K13: =F13 -> 12 | L13: =G13*(15/20) -> 6 | M13: =(LARGE(I13:L13,1)+LARGE(I13:L13,2)+LARGE(I13:L13,3))/3 -> 9.5
A14: =A13+1 -> 9 | B14: 24341037 | C14: Abrar Yaman Reza | D14: 6 | E14: 17 | F14: 14 | G14: 19 | I14: =D14*(15/20) -> 4.5 | J14: =E14*(15/20) -> 12.75 | K14: =F14 -> 14 | L14: =G14*(15/20) -> 14.25 | M14: =(LARGE(I14:L14,1)+LARGE(I14:L14,2)+LARGE(I14:L14,3))/3 -> 13.666667
A15: =A14+1 -> 10 | B15: 24201116 | C15: Zarif Tausif Ahmed Nafi | D15: 18 | E15: 18 | F15: 13 | G15: 9 | I15: =D15*(15/20) -> 13.5 | J15: =E15*(15/20) -> 13.5 | K15: =F15 -> 13 | L15: =G15*(15/20) -> 6.75 | M15: =(LARGE(I15:L15,1)+LARGE(I15:L15,2)+LARGE(I15:L15,3))/3 -> 13.333333
A16: =A15+1 -> 11 | B16: 22101447 | C16: Showrav Sutradhar | D16: 4 | I16: =D16*(15/20) -> 3 | J16: =E16*(15/20) -> 0 | K16: =F16 | L16: =G16*(15/20) -> 0 | M16: =(LARGE(I16:L16,1)+LARGE(I16:L16,2)+LARGE(I16:L16,3))/3 -> 1
A17: =A16+1 -> 12 | B17: 22201450 | C17: Mamduha Akter | D17: 12 | E17: 13 | F17: 14 | G17: 7 | I17: =D17*(15/20) -> 9 | J17: =E17*(15/20) -> 9.75 | K17: =F17 -> 14 | L17: =G17*(15/20) -> 5.25 | M17: =(LARGE(I17:L17,1)+LARGE(I17:L17,2)+LARGE(I17:L17,3))/3 -> 10.916667
A18: =A17+1 -> 13 | B18: 23301249 | C18: Md. Rafsan Elahi | D18: 8 | E18: 13 | F18: 14 | G18: 17 | I18: =D18*(15/20) -> 6 | J18: =E18*(15/20) -> 9.75 | K18: =F18 -> 14 | L18: =G18*(15/20) -> 12.75 | M18: =(LARGE(I18:L18,1)+LARGE(I18:L18,2)+LARGE(I18:L18,3))/3 -> 12.166667
A19: =A18+1 -> 14 | B19: 24301057 | C19: Zarif Abrar Jamil | D19: 15 | E19: 14 | F19: 8 | G19: 13 | I19: =D19*(15/20) -> 11.25 | J19: =E19*(15/20) -> 10.5 | K19: =F19 -> 8 | L19: =G19*(15/20) -> 9.75 | M19: =(LARGE(I19:L19,1)+LARGE(I19:L19,2)+LARGE(I19:L19,3))/3 -> 10.5
A20: =A19+1 -> 15 | B20: 24301115 | C20: Nusrat Jahan | D20: 14 | E20: 10 | F20: 13 | I20: =D20*(15/20) -> 10.5 | J20: =E20*(15/20) -> 7.5 | K20: =F20 -> 13 | L20: =G20*(15/20) -> 0 | M20: =(LARGE(I20:L20,1)+LARGE(I20:L20,2)+LARGE(I20:L20,3))/3 -> 10.333333
A21: =A20+1 -> 16 | B21: 24301414 | C21: Khandaker Madiha Muminah | D21: 11 | E21: 16 | F21: 5 | G21: 15 | I21: =D21*(15/20) -> 8.25 | J21: =E21*(15/20) -> 12 | K21: =F21 -> 5 | L21: =G21*(15/20) -> 11.25 | M21: =(LARGE(I21:L21,1)+LARGE(I21:L21,2)+LARGE(I21:L21,3))/3 -> 10.5
A22: =A21+1 -> 17 | B22: 24201260 | C22: Md.Abdullah-Al-Kafi | D22: 15 | E22: 13 | G22: 12 | I22: =D22*(15/20) -> 11.25 | J22: =E22*(15/20) -> 9.75 | K22: =F22 | L22: =G22*(15/20) -> 9 | M22: =(LARGE(I22:L22,1)+LARGE(I22:L22,2)+LARGE(I22:L22,3))/3 -> 10
A23: =A22+1 -> 18 | B23: 24201244 | C23: Ifran Hossain Sazid | D23: 6 | I23: =D23*(15/20) -> 4.5 | J23: =E23*(15/20) -> 0 | K23: =F23 | L23: =G23*(15/20) -> 0 | M23: =(LARGE(I23:L23,1)+LARGE(I23:L23,2)+LARGE(I23:L23,3))/3 -> 1.5
A24: =A23+1 -> 19 | B24: 24201366 | C24: Lamiea Amzad Suhana | D24: 19 | E24: 10 | F24: 14 | G24: 10 | I24: =D24*(15/20) -> 14.25 | J24: =E24*(15/20) -> 7.5 | K24: =F24 -> 14 | L24: =G24*(15/20) -> 7.5 | M24: =(LARGE(I24:L24,1)+LARGE(I24:L24,2)+LARGE(I24:L24,3))/3 -> 11.916667
A25: =A24+1 -> 20 | B25: =B24+1 -> 24201367 | C25: Faria Fannana Toree | D25: 16 | E25: 17 | F25: 14 | G25: 12 | I25: =D25*(15/20) -> 12 | J25: =E25*(15/20) -> 12.75 | K25: =F25 -> 14 | L25: =G25*(15/20) -> 9 | M25: =(LARGE(I25:L25,1)+LARGE(I25:L25,2)+LARGE(I25:L25,3))/3 -> 12.916667
A26: =A25+1 -> 21 | B26: 1000054019 | C26: Md. Abrarul Haque Pathan | D26: 15 | E26: 12 | F26: 13 | G26: 9 | I26: =D26*(15/20) -> 11.25 | J26: =E26*(15/20) -> 9 | K26: =F26 -> 13 | L26: =G26*(15/20) -> 6.75 | M26: =(LARGE(I26:L26,1)+LARGE(I26:L26,2)+LARGE(I26:L26,3))/3 -> 11.083333
A27: =A26+1 -> 22 | B27: 1000054082 | C27: Kamruzzaman Chowdhury | D27: 18 | E27: 7 | F27: 15 | G27: 9 | I27: =D27*(15/20) -> 13.5 | J27: =E27*(15/20) -> 5.25 | K27: =F27 -> 15 | L27: =G27*(15/20) -> 6.75 | M27: =(LARGE(I27:L27,1)+LARGE(I27:L27,2)+LARGE(I27:L27,3))/3 -> 11.75
A28: =A27+1 -> 23 | B28: 1000054210 | C28: Adnan Tazbir Arian | D28: 10 | E28: 10 | F28: 11 | I28: =D28*(15/20) -> 7.5 | J28: =E28*(15/20) -> 7.5 | K28: =F28 -> 11 | L28: =G28*(15/20) -> 0 | M28: =(LARGE(I28:L28,1)+LARGE(I28:L28,2)+LARGE(I28:L28,3))/3 -> 8.6666667
A29: =A28+1 -> 24 | B29: 1000054898 | C29: Ryan Amin | D29: 19 | E29: 19 | F29: 14 | G29: 16 | I29: =D29*(15/20) -> 14.25 | J29: =E29*(15/20) -> 14.25 | K29: =F29 -> 14 | L29: =G29*(15/20) -> 12 | M29: =(LARGE(I29:L29,1)+LARGE(I29:L29,2)+LARGE(I29:L29,3))/3 -> 14.166667
A30: =A29+1 -> 25 | B30: 1000054905 | C30: Md. Yasin Islam Khan | D30: 14 | E30: 1 | F30: 12 | G30: 10 | I30: =D30*(15/20) -> 10.5 | J30: =E30*(15/20) -> 0.75 | K30: =F30 -> 12 | L30: =G30*(15/20) -> 7.5 | M30: =(LARGE(I30:L30,1)+LARGE(I30:L30,2)+LARGE(I30:L30,3))/3 -> 10
A31: =A30+1 -> 26 | B31: 1000055328 | C31: Mos. Tawhida Rahman Tasfia | D31: 18 | E31: 18 | F31: 14 | G31: 12 | I31: =D31*(15/20) -> 13.5 | J31: =E31*(15/20) -> 13.5 | K31: =F31 -> 14 | L31: =G31*(15/20) -> 9 | M31: =(LARGE(I31:L31,1)+LARGE(I31:L31,2)+LARGE(I31:L31,3))/3 -> 13.666667
A32: =A31+1 -> 27 | B32: 1000055346 | C32: Emranul Haq Atonu | D32: 14 | E32: 1 | F32: 12 | G32: 10 | I32: =D32*(15/20) -> 10.5 | J32: =E32*(15/20) -> 0.75 | K32: =F32 -> 12 | L32: =G32*(15/20) -> 7.5 | M32: =(LARGE(I32:L32,1)+LARGE(I32:L32,2)+LARGE(I32:L32,3))/3 -> 10
A33: =A32+1 -> 28 | B33: 1000055421 | C33: Nazia Tabassum Nawmee | D33: 5 | E33: 18 | F33: 15 | G33: 18 | I33: =D33*(15/20) -> 3.75 | J33: =E33*(15/20) -> 13.5 | K33: =F33 -> 15 | L33: =G33*(15/20) -> 13.5 | M33: =(LARGE(I33:L33,1)+LARGE(I33:L33,2)+LARGE(I33:L33,3))/3 -> 14
A34: =A33+1 -> 29 | B34: 23101383 | C34: Raduan Rahman Ridoy | D34: 18 | E34: 15 | F34: 11 | G34: 17 | I34: =D34*(15/20) -> 13.5 | J34: =E34*(15/20) -> 11.25 | K34: =F34 -> 11 | L34: =G34*(15/20) -> 12.75 | M34: =(LARGE(I34:L34,1)+LARGE(I34:L34,2)+LARGE(I34:L34,3))/3 -> 12.5
A35: =A34+1 -> 30 | B35: 24121350 | C35: Md.Fahim Muntasir | I35: =D35*(15/20) -> 0 | J35: =E35*(15/20) -> 0 | K35: =F35 | L35: =G35*(15/20) -> 0 | M35: =(LARGE(I35:L35,1)+LARGE(I35:L35,2)+LARGE(I35:L35,3))/3 -> 0
A36: =A35+1 -> 31 | B36: 1000058970 | C36: Amitrakshar Biswas | D36: 20 | E36: 20 | F36: 14 | G36: 17 | I36: =D36*(15/20) -> 15 | J36: =E36*(15/20) -> 15 | K36: =F36 -> 14 | L36: =G36*(15/20) -> 12.75 | M36: =(LARGE(I36:L36,1)+LARGE(I36:L36,2)+LARGE(I36:L36,3))/3 -> 14.666667
A37: =A36+1 -> 32 | B37: 24321209 | C37: Subhaha Israth Jahaan | D37: 12 | E37: 11 | F37: 13 | G37: 8 | I37: =D37*(15/20) -> 9 | J37: =E37*(15/20) -> 8.25 | K37: =F37 -> 13 | L37: =G37*(15/20) -> 6 | M37: =(LARGE(I37:L37,1)+LARGE(I37:L37,2)+LARGE(I37:L37,3))/3 -> 10.083333
A38: =A37+1 -> 33 | B38: 24121314 | C38: Mostofa Galib | I38: =D38*(15/20) -> 0 | J38: =E38*(15/20) -> 0 | K38: =F38 | L38: =G38*(15/20) -> 0 | M38: =(LARGE(I38:L38,1)+LARGE(I38:L38,2)+LARGE(I38:L38,3))/3 -> 0
A39: =A38+1 -> 34 | B39: 24101166 | C39: Tahsin Ahmed | D39: 11 | I39: =D39*(15/20) -> 8.25 | J39: =E39*(15/20) -> 0 | K39: =F39 | L39: =G39*(15/20) -> 0 | M39: =(LARGE(I39:L39,1)+LARGE(I39:L39,2)+LARGE(I39:L39,3))/3 -> 2.75
A40: =A39+1 -> 35 | B40: 24321189 | C40: A K M Amirul Muminin Sadi | D40: 11 | E40: 14 | F40: 8 | G40: 11 | I40: =D40*(15/20) -> 8.25 | J40: =E40*(15/20) -> 10.5 | K40: =F40 -> 8 | L40: =G40*(15/20) -> 8.25 | M40: =(LARGE(I40:L40,1)+LARGE(I40:L40,2)+LARGE(I40:L40,3))/3 -> 9
A41: =A40+1 -> 36 | B41: 23301466 | C41: Shadman Sakib | D41: 14 | E41: 10 | F41: 12 | G41: 13 | I41: =D41*(15/20) -> 10.5 | J41: =E41*(15/20) -> 7.5 | K41: =F41 -> 12 | L41: =G41*(15/20) -> 9.75 | M41: =(LARGE(I41:L41,1)+LARGE(I41:L41,2)+LARGE(I41:L41,3))/3 -> 10.75
A42: =A41+1 -> 37 | B42: 1000054061 | C42: Sikder Atif Abrar | D42: 15 | E42: 8 | F42: 14 | G42: 14 | I42: =D42*(15/20) -> 11.25 | J42: =E42*(15/20) -> 6 | K42: =F42 -> 14 | L42: =G42*(15/20) -> 10.5 | M42: =(LARGE(I42:L42,1)+LARGE(I42:L42,2)+LARGE(I42:L42,3))/3 -> 11.916667
A43: =A42+1 -> 38 | B43: 24321241 | C43: Tasnimul Hassan | D43: 18 | F43: 15 | G43: 16 | I43: =D43*(15/20) -> 13.5 | J43: =E43*(15/20) -> 0 | K43: =F43 -> 15 | L43: =G43*(15/20) -> 12 | M43: =(LARGE(I43:L43,1)+LARGE(I43:L43,2)+LARGE(I43:L43,3))/3 -> 13.5
...

Sheet Mid Marks
B2: Mid Marks
A5: SL | B5: Student Id | C5: Name | D5: Q1 6 Marks | E5: Q2 8 Marks | F5: Q3 6 Marks | G5: Q4 10 Marks | H5: Total 30 Marks | I5: Total 25%
A6: 1 | B6: 22301333 | C6: Nazmus Sakib | D6: 3 | F6: 3 | G6: 4 | H6: =SUM(D6:G6) -> 10 | I6: =H6*(25/30) -> 8.3333333
A7: =A6+1 -> 2 | B7: 23301549 | C7: Navid Mahmood | D7: 3 | E7: 1 | F7: 5 | G7: 7 | H7: =SUM(D7:G7) -> 16 | I7: =H7*(25/30) -> 13.333333
A8: =A7+1 -> 3 | B8: 23301673 | C8: Mahiba Tasnim | D8: 3 | E8: 4 | G8: 3 | H8: =SUM(D8:G8) -> 10 | I8: =H8*(25/30) -> 8.3333333
A9: =A8+1 -> 4 | B9: 23201533 | C9: Nusrat Jahan Arpa | D9: 1 | E9: 3 | F9: 3 | G9: 3 | H9: =SUM(D9:G9) -> 10 | I9: =H9*(25/30) -> 8.3333333
A10: =A9+1 -> 5 | B10: 24101194 | C10: Ohi Ahmed | D10: 2 | E10: 7 | F10: 5 | G10: 7 | H10: =SUM(D10:G10) -> 21 | I10: =H10*(25/30) -> 17.5
A11: =A10+1 -> 6 | B11: 24101253 | C11: Md. Asiful Islam | D11: 5 | E11: 2 | F11: 5 | G11: 7 | H11: =SUM(D11:G11) -> 19 | I11: =H11*(25/30) -> 15.833333
A12: =A11+1 -> 7 | B12: 24301317 | C12: Ashmita Deb Nath | D12: 3 | E12: 4 | F12: 3 | G12: 5 | H12: =SUM(D12:G12) -> 15 | I12: =H12*(25/30) -> 12.5
A13: =A12+1 -> 8 | B13: 24301488 | C13: Obontika Rashid Prethula | D13: 3 | E13: 3 | F13: 4 | G13: 5 | H13: =SUM(D13:G13) -> 15 | I13: =H13*(25/30) -> 12.5
A14: =A13+1 -> 9 | B14: 24341037 | C14: Abrar Yaman Reza | D14: 5 | E14: 3 | F14: 2 | G14: 7 | H14: =SUM(D14:G14) -> 17 | I14: =H14*(25/30) -> 14.166667
A15: =A14+1 -> 10 | B15: 24201116 | C15: Zarif Tausif Ahmed Nafi | D15: 5 | E15: 5 | F15: 2 | G15: 8 | H15: =SUM(D15:G15) -> 20 | I15: =H15*(25/30) -> 16.666667
A16: =A15+1 -> 11 | B16: 22101447 | C16: Showrav Sutradhar | D16: 3 | E16: 3 | F16: 2 | G16: 2 | H16: =SUM(D16:G16) -> 10 | I16: =H16*(25/30) -> 8.3333333
A17: =A16+1 -> 12 | B17: 22201450 | C17: Mamduha Akter | D17: 3 | E17: 3 | F17: 3 | G17: 3 | H17: =SUM(D17:G17) -> 12 | I17: =H17*(25/30) -> 10
A18: =A17+1 -> 13 | B18: 23301249 | C18: Md. Rafsan Elahi | D18: 5 | E18: 3 | G18: 5 | H18: =SUM(D18:G18) -> 13 | I18: =H18*(25/30) -> 10.833333
A19: =A18+1 -> 14 | B19: 24301057 | C19: Zarif Abrar Jamil | D19: 3 | E19: 3 | F19: 1 | G19: 7 | H19: =SUM(D19:G19) -> 14 | I19: =H19*(25/30) -> 11.666667
A20: =A19+1 -> 15 | B20: 24301115 | C20: Nusrat Jahan | D20: 5 | E20: 4 | F20: 5 | G20: 9 | H20: =SUM(D20:G20) -> 23 | I20: =H20*(25/30) -> 19.166667
A21: =A20+1 -> 16 | B21: 24301414 | C21: Khandaker Madiha Muminah | D21: 3 | E21: 4 | F21: 5 | G21: 5 | H21: =SUM(D21:G21) -> 17 | I21: =H21*(25/30) -> 14.166667
A22: =A21+1 -> 17 | B22: 24201260 | C22: Md.Abdullah-Al-Kafi | D22: 3 | E22: 4 | F22: 3 | G22: 6 | H22: =SUM(D22:G22) -> 16 | I22: =H22*(25/30) -> 13.333333
A23: =A22+1 -> 18 | B23: 24201244 | C23: Ifran Hossain Sazid | D23: 5 | F23: 6 | G23: 2 | H23: =SUM(D23:G23) -> 13 | I23: =H23*(25/30) -> 10.833333
A24: =A23+1 -> 19 | B24: 24201366 | C24: Lamiea Amzad Suhana | D24: 3 | E24: 3 | F24: 3 | G24: 2 | H24: =SUM(D24:G24) -> 11 | I24: =H24*(25/30) -> 9.1666667
A25: =A24+1 -> 20 | B25: 24215001 | C25: Faria Fannana Toree | D25: 5 | E25: 4 | F25: 5 | G25: 6 | H25: =SUM(D25:G25) -> 20 | I25: =H25*(25/30) -> 16.666667
A26: =A25+1 -> 21 | B26: 1000054019 | C26: Md. Abrarul Haque Pathan | D26: 3 | E26: 3 | F26: 3 | G26: 9 | H26: =SUM(D26:G26) -> 18 | I26: =H26*(25/30) -> 15
A27: =A26+1 -> 22 | B27: 1000054082 | C27: Kamruzzaman Chowdhury | D27: 5 | E27: 8 | F27: 3 | G27: 10 | H27: =SUM(D27:G27) -> 26 | I27: =H27*(25/30) -> 21.666667
A28: =A27+1 -> 23 | B28: 1000054210 | C28: Adnan Tazbir Arian | D28: 3 | E28: 3 | F28: 4 | G28: 7 | H28: =SUM(D28:G28) -> 17 | I28: =H28*(25/30) -> 14.166667
A29: =A28+1 -> 24 | B29: 1000054898 | C29: Ryan Amin | D29: 4 | E29: 4 | F29: 4 | G29: 8 | H29: =SUM(D29:G29) -> 20 | I29: =H29*(25/30) -> 16.666667
A30: =A29+1 -> 25 | B30: 1000054905 | C30: Md. Yasin Islam Khan | D30: 4 | E30: 4 | F30: 5 | G30: 8 | H30: =SUM(D30:G30) -> 21 | I30: =H30*(25/30) -> 17.5
A31: =A30+1 -> 26 | B31: 1000055328 | C31: Mos. Tawhida Rahman Tasfia | D31: 5 | E31: 5 | F31: 5 | G31: 9 | H31: =SUM(D31:G31) -> 24 | I31: =H31*(25/30) -> 20
A32: =A31+1 -> 27 | B32: 1000055346 | C32: Emranul Haq Atonu | D32: 5 | E32: 3 | F32: 6 | G32: 10 | H32: =SUM(D32:G32) -> 24 | I32: =H32*(25/30) -> 20
A33: =A32+1 -> 28 | B33: 1000055421 | C33: Nazia Tabassum Nawmee | D33: 3 | E33: 4 | F33: 4 | G33: 6 | H33: =SUM(D33:G33) -> 17 | I33: =H33*(25/30) -> 14.166667
A34: =A33+1 -> 29 | B34: 23101383 | C34: Raduan Rahman Ridoy | D34: 4 | E34: 3 | F34: 4 | G34: 10 | H34: =SUM(D34:G34) -> 21 | I34: =H34*(25/30) -> 17.5
A35: =A34+1 -> 30 | B35: 24121350 | C35: Md.Fahim Muntasir | D35: 4 | E35: 5 | F35: 4 | G35: 3 | H35: =SUM(D35:G35) -> 16 | I35: =H35*(25/30) -> 13.333333
... A37: =A36+1 -> 32 | B37: 24321209 | C37: Subhaha Israth Jahaan | D37: 5 | E37: 3 | F37: 4 | G37: 7 | H37: =SUM(D37:G37) -> 19 | I37: =H37*(25/30) -> 15.833333
A38: =A37+1 -> 33 | B38: 24121314 | C38: Mostofa Galib | H38: =SUM(D38:G38) -> 0 | I38: =H38*(25/30) -> 0
A39: =A38+1 -> 34 | B39: 24101166 | C39: Tahsin Ahmed | D39: 1 | E39: 3 | F39: 4 | G39: 3 | H39: =SUM(D39:G39) -> 11 | I39: =H39*(25/30) -> 9.1666667
A40: =A39+1 -> 35 | B40: 24321189 | C40: A K M Amirul Muminin Sadi | D40: 5 | E40: 4 | F40: 5 | G40: 5 | H40: =SUM(D40:G40) -> 19 | I40: =H40*(25/30) -> 15.833333
A41: =A40+1 -> 36 | B41: 23301466 | C41: Shadman Sakib | D41: 3 | E41: 3 | F41: 4 | G41: 8 | H41: =SUM(D41:G41) -> 18 | I41: =H41*(25/30) -> 15
A42: =A41+1 -> 37 | B42: 1000054061 | C42: Sikder Atif Abrar | D42: 5 | E42: 7 | F42: 6 | G42: 9 | H42: =SUM(D42:G42) -> 27 | I42: =H42*(25/30) -> 22.5
A43: =A42+1 -> 38 | B43: 24321241 | C43: Tasnimul Hassan | D43: 3 | E43: 4 | F43: 4 | G43: 9 | H43: =SUM(D43:G43) -> 20 | I43: =H43*(25/30) -> 16.666667
A44: =A43+1 -> 39 | B44: 24321176 | C44: Talha Bin Salam | D44: 2 | E44: 3 | F44: 5 | G44: 3 | H44: =SUM(D44:G44) -> 13 | I44: =H44*(25/30) -> 10.833333
...

Sheet Final Marks
B2: Final Marks
A5: SL | B5: Student Id | C5: Name | D5: Q1 (6 marks) | E5: Q2 (8 marks) | F5: Q3 (4 marks) | G5: Q4 (6 marks) | H5: Q5 (11 marks) | I5: Total
A6: 1 | B6: 22301333 | C6: Nazmus Sakib | D6: 2 | E6: 2 | F6: 2 | G6: 3 | H6: 6 | I6: =SUM(D6:H6) -> 15
A7: =A6+1 -> 2 | B7: 23301549 | C7: Navid Mahmood | D7: 2 | E7: 2 | F7: 2 | G7: 6 | H7: 10 | I7: =SUM(D7:H7) -> 22
A8: =A7+1 -> 3 | B8: 23301673 | C8: Mahiba Tasnim | D8: 1 | E8: 2 | F8: 2 | H8: 4 | I8: =SUM(D8:H8) -> 9
A9: =A8+1 -> 4 | B9: 23201533 | C9: Nusrat Jahan Arpa | D9: 2 | E9: 4 | F9: 3 | G9: 2 | H9: 4 | I9: =SUM(D9:H9) -> 15
A10: =A9+1 -> 5 | B10: 24101194 | C10: Ohi Ahmed | E10: 6 | F10: 3 | G10: 2 | H10: 5 | I10: =SUM(D10:H10) -> 16
A11: =A10+1 -> 6 | B11: 24101253 | C11: Md. Asiful Islam | D11: 4 | E11: 3 | F11: 2 | G11: 2 | H11: 6 | I11: =SUM(D11:H11) -> 17
A12: =A11+1 -> 7 | B12: 24301317 | C12: Ashmita Deb Nath | D12: 3 | E12: 3 | F12: 2 | G12: 2 | H12: 3 | I12: =SUM(D12:H12) -> 13
A13: =A12+1 -> 8 | B13: 24301488 | C13: Obontika Rashid Prethula | D13: 2 | E13: 3 | F13: 2 | G13: 2 | H13: 6 | I13: =SUM(D13:H13) -> 15
A14: =A13+1 -> 9 | B14: 24341037 | C14: Abrar Yaman Reza | D14: 2 | E14: 6 | F14: 4 | G14: 6 | H14: 6 | I14: =SUM(D14:H14) -> 24
A15: =A14+1 -> 10 | B15: 24201116 | C15: Zarif Tausif Ahmed Nafi | D15: 4 | E15: 6 | F15: 2 | G15: 6 | H15: 8 | I15: =SUM(D15:H15) -> 26
A16: =A15+1 -> 11 | B16: 22101447 | C16: Showrav Sutradhar | I16: =SUM(D16:H16) -> 0 | S16: =SUM(I6:I45) -> 721
A17: =A16+1 -> 12 | B17: 22201450 | C17: Mamduha Akter | D17: 3 | E17: 3 | F17: 2 | G17: 2 | H17: 7 | I17: =SUM(D17:H17) -> 17 | S17: =S16/34 -> 21.205882
A18: =A17+1 -> 13 | B18: 23301249 | C18: Md. Rafsan Elahi | D18: 5 | E18: 6 | F18: 1 | G18: 4 | H18: 5 | I18: =SUM(D18:H18) -> 21
A19: =A18+1 -> 14 | B19: 24301057 | C19: Zarif Abrar Jamil | D19: 2 | E19: 4 | F19: 2 | G19: 6 | H19: 10 | I19: =SUM(D19:H19) -> 24
A20: =A19+1 -> 15 | B20: 24301115 | C20: Nusrat Jahan | D20: 4 | E20: 5 | F20: 3 | G20: 6 | H20: 10 | I20: =SUM(D20:H20) -> 28
A21: =A20+1 -> 16 | B21: 24301414 | C21: Khandaker Madiha Muminah | D21: 6 | E21: 4 | F21: 2 | G21: 6 | H21: 6 | I21: =SUM(D21:H21) -> 24
A22: =A21+1 -> 17 | B22: 24201260 | C22: Md.Abdullah-Al-Kafi | D22: 5 | E22: 4 | F22: 2 | G22: 2 | H22: 7 | I22: =SUM(D22:H22) -> 20
A23: =A22+1 -> 18 | B23: 24201244 | C23: Ifran Hossain Sazid | I23: =SUM(D23:H23) -> 0
A24: =A23+1 -> 19 | B24: 24201366 | C24: Lamiea Amzad Suhana | D24: 3 | E24: 3 | F24: 2 | H24: 6 | I24: =SUM(D24:H24) -> 14
A25: =A24+1 -> 20 | B25: =B24+1 -> 24201367 | C25: Faria Fannana Toree | D25: 6 | E25: 4 | F25: 3 | G25: 2 | H25: 9 | I25: =SUM(D25:H25) -> 24
A26: =A25+1 -> 21 | B26: 1000054019 | C26: Md. Abrarul Haque Pathan | D26: 2 | E26: 4 | F26: 3 | G26: 1 | H26: 8 | I26: =SUM(D26:H26) -> 18
A27: =A26+1 -> 22 | B27: 1000054082 | C27: Kamruzzaman Chowdhury | D27: 5 | E27: 5 | F27: 3 | G27: 6 | H27: 8 | I27: =SUM(D27:H27) -> 27
A28: =A27+1 -> 23 | B28: 1000054210 | C28: Adnan Tazbir Arian | D28: 3 | E28: 8 | F28: 3 | G28: 5 | H28: 5 | I28: =SUM(D28:H28) -> 24
A29: =A28+1 -> 24 | B29: 1000054898 | C29: Ryan Amin | D29: 3 | E29: 3 | F29: 2 | H29: 7 | I29: =SUM(D29:H29) -> 15
A30: =A29+1 -> 25 | B30: 1000054905 | C30: Md. Yasin Islam Khan | D30: 2 | E30: 3 | F30: 2 | G30: 1 | H30: 7 | I30: =SUM(D30:H30) -> 15
A31: =A30+1 -> 26 | B31: 1000055328 | C31: Mos. Tawhida Rahman Tasfia | D31: 6 | E31: 6 | F31: 2 | G31: 6 | H31: 7 | I31: =SUM(D31:H31) -> 27
A32: =A31+1 -> 27 | B32: 1000055346 | C32: Emranul Haq Atonu | D32: 4 | E32: 3 | F32: 3 | G32: 6 | H32: 10 | I32: =SUM(D32:H32) -> 26
A33: =A32+1 -> 28 | B33: 1000055421 | C33: Nazia Tabassum Nawmee | D33: 5 | E33: 4 | F33: 2 | G33: 5 | H33: 5 | I33: =SUM(D33:H33) -> 21
A34: =A33+1 -> 29 | B34: 23101383 | C34: Raduan Rahman Ridoy | D34: 3 | E34: 3 | F34: 3 | G34: 6 | H34: 9 | I34: =SUM(D34:H34) -> 24
A35: =A34+1 -> 30 | B35: 24121350 | C35: Md.Fahim Muntasir | I35: =SUM(D35:H35) -> 0
A36: =A35+1 -> 31 | B36: 1000058970 | C36: Amitrakshar Biswas | D36: 6 | E36: 8 | F36: 4 | G36: 6 | H36: 11 | I36: =SUM(D36:H36) -> 35
A37: =A36+1 -> 32 | B37: 24321209 | C37: Subhaha Israth Jahaan | D37: 3 | E37: 3 | F37: 2 | G37: 6 | H37: 8 | I37: =SUM(D37:H37) -> 22
A38: =A37+1 -> 33 | B38: 24121314 | C38: Mostofa Galib | I38: =SUM(D38:H38) -> 0
A39: =A38+1 -> 34 | B39: 24101166 | C39: Tahsin Ahmed | I39: =SUM(D39:H39) -> 0
A40: =A39+1 -> 35 | B40: 24321189 | C40: A K M Amirul Muminin Sadi | D40: 3 | E40: 3 | F40: 3 | G40: 6 | H40: 6 | I40: =SUM(D40:H40) -> 21
A41: =A40+1 -> 36 | B41: 23301466 | C41: Shadman Sakib | D41: 5 | E41: 4 | F41: 2 | G41: 6 | H41: 8 | I41: =SUM(D41:H41) -> 25
A42: =A41+1 -> 37 | B42: 1000054061 | C42: Sikder Atif Abrar | D42: 6 | E42: 8 | F42: 3 | G42: 6 | H42: 8 | I42: =SUM(D42:H42) -> 31
A43: =A42+1 -> 38 | B43: 24321241 | C43: Tasnimul Hassan | I43: =SUM(D43:H43) -> 0
...

Sheet Gradesheet
B4: GRADESHEET CSE220 ~ 12
A7: Sl | B7: Student Id | C7: Name | D7: Quiz (15%) | E7: Lab (25%) | F7: Mid (25%) | G7: Finals (35%) | H7: Total (100 Marks) | I7: Total (100% Marks) | J7: GRADES
A8: 1 | B8: 22301333 | C8: Nazmus Sakib | D8: ='Quiz Marks'!M6 -> 13.166667 | E8: 13.3 | F8: ='Mid Marks'!I6 -> 8.3333333 | G8: ='Final Marks'!I6 -> 15 | H8: =SUM(D8:G8) -> 49.8 | I8: =IF(AND(H8>=96.5,H8<97),H8,ROUND(H8,0)) -> 50 | J8: =IF(I8<65,IF(I8<55,IF(I8<52,IF(I8<50,"F","D-"),"D"),IF(I8<57,"D+",IF(I8<60,"C-","C"))),IF(I8<75,IF(I8<70,"C+","B-"),IF(I8<85,IF(I8<80,"B","B+"),IF(I8<90,"A-",IF(I8<97,"A","A+"))))) -> D-
A9: =A8+1 -> 2 | B9: 23301549 | C9: Navid Mahmood | D9: ='Quiz Marks'!M7 -> 10.416667 | E9: 9.5 | F9: ='Mid Marks'!I7 -> 13.333333 | G9: ='Final Marks'!I7 -> 22 | H9: =SUM(D9:G9) -> 55.25 | I9: =IF(AND(H9>=96.5,H9<97),H9,ROUND(H9,0)) -> 55 | J9: =IF(I9<65,IF(I9<55,IF(I9<52,IF(I9<50,"F","D-"),"D"),IF(I9<57,"D+",IF(I9<60,"C-","C"))),IF(I9<75,IF(I9<70,"C+","B-"),IF(I9<85,IF(I9<80,"B","B+"),IF(I9<90,"A-",IF(I9<97,"A","A+"))))) -> D+
A10: =A9+1 -> 3 | B10: 23301673 | C10: Mahiba Tasnim | D10: ='Quiz Marks'!M8 -> 3.4166667 | E10: 14.2 | F10: ='Mid Marks'!I8 -> 8.3333333 | G10: ='Final Marks'!I8 -> 9 | H10: =SUM(D10:G10) -> 34.95 | I10: =IF(AND(H10>=96.5,H10<97),H10,ROUND(H10,0)) -> 35 | J10: =IF(I10<65,IF(I10<55,IF(I10<52,IF(I10<50,"F","D-"),"D"),IF(I10<57,"D+",IF(I10<60,"C-","C"))),IF(I10<75,IF(I10<70,"C+","B-"),IF(I10<85,IF(I10<80,"B","B+"),IF(I10<90,"A-",IF(I10<97,"A","A+"))))) -> F
A11: =A10+1 -> 4 | B11: 23201533 | C11: Nusrat Jahan Arpa | D11: ='Quiz Marks'!M9 -> 13.416667 | E11: 23.2 | F11: ='Mid Marks'!I9 -> 8.3333333 | G11: ='Final Marks'!I9 -> 15 | H11: =SUM(D11:G11) -> 59.95 | I11: =IF(AND(H11>=96.5,H11<97),H11,ROUND(H11,0)) -> 60 | J11: =IF(I11<65,IF(I11<55,IF(I11<52,IF(I11<50,"F","D-"),"D"),IF(I11<57,"D+",IF(I11<60,"C-","C"))),IF(I11<75,IF(I11<70,"C+","B-"),IF(I11<85,IF(I11<80,"B","B+"),IF(I11<90,"A-",IF(I11<97,"A","A+"))))) -> C
A12: =A11+1 -> 5 | B12: 24101194 | C12: Ohi Ahmed | D12: ='Quiz Marks'!M10 -> 11.25 | E12: 16.9 | F12: ='Mid Marks'!I10 -> 17.5 | G12: ='Final Marks'!I10 -> 16 | H12: =SUM(D12:G12) -> 61.65 | I12: =IF(AND(H12>=96.5,H12<97),H12,ROUND(H12,0)) -> 62 | J12: =IF(I12<65,IF(I12<55,IF(I12<52,IF(I12<50,"F","D-"),"D"),IF(I12<57,"D+",IF(I12<60,"C-","C"))),IF(I12<75,IF(I12<70,"C+","B-"),IF(I12<85,IF(I12<80,"B","B+"),IF(I12<90,"A-",IF(I12<97,"A","A+"))))) -> C
A13: =A12+1 -> 6 | B13: 24101253 | C13: Md. Asiful Islam | D13: ='Quiz Marks'!M11 -> 12.083333 | E13: 19.9 | F13: ='Mid Marks'!I11 -> 15.833333 | G13: ='Final Marks'!I11 -> 17 | H13: =SUM(D13:G13) -> 64.816667 | I13: =IF(AND(H13>=96.5,H13<97),H13,ROUND(H13,0)) -> 65 | J13: =IF(I13<65,IF(I13<55,IF(I13<52,IF(I13<50,"F","D-"),"D"),IF(I13<57,"D+",IF(I13<60,"C-","C"))),IF(I13<75,IF(I13<70,"C+","B-"),IF(I13<85,IF(I13<80,"B","B+"),IF(I13<90,"A-",IF(I13<97,"A","A+"))))) -> C+
A14: =A13+1 -> 7 | B14: 24301317 | C14: Ashmita Deb Nath | D14: ='Quiz Marks'!M12 -> 10.083333 | E14: 17.1 | F14: ='Mid Marks'!I12 -> 12.5 | G14: ='Final Marks'!I12 -> 13 | H14: =SUM(D14:G14) -> 52.683333 | I14: =IF(AND(H14>=96.5,H14<97),H14,ROUND(H14,0)) -> 53 | J14: =IF(I14<65,IF(I14<55,IF(I14<52,IF(I14<50,"F","D-"),"D"),IF(I14<57,"D+",IF(I14<60,"C-","C"))),IF(I14<75,IF(I14<70,"C+","B-"),IF(I14<85,IF(I14<80,"B","B+"),IF(I14<90,"A-",IF(I14<97,"A","A+"))))) -> D
A15: =A14+1 -> 8 | B15: 24301488 | C15: Obontika Rashid Prethula | D15: ='Quiz Marks'!M13 -> 9.5 | E15: 13.2 | F15: ='Mid Marks'!I13 -> 12.5 | G15: ='Final Marks'!I13 -> 15 | H15: =SUM(D15:G15) -> 50.2 | I15: =IF(AND(H15>=96.5,H15<97),H15,ROUND(H15,0)) -> 50 | J15: =IF(I15<65,IF(I15<55,IF(I15<52,IF(I15<50,"F","D-"),"D"),IF(I15<57,"D+",IF(I15<60,"C-","C"))),IF(I15<75,IF(I15<70,"C+","B-"),IF(I15<85,IF(I15<80,"B","B+"),IF(I15<90,"A-",IF(I15<97,"A","A+"))))) -> D-
A16: =A15+1 -> 9 | B16: 24341037 | C16: Abrar Yaman Reza | D16: ='Quiz Marks'!M14 -> 13.666667 | E16: 23.1 | F16: ='Mid Marks'!I14 -> 14.166667 | G16: ='Final Marks'!I14 -> 24 | H16: =SUM(D16:G16) -> 74.933333 | I16: =IF(AND(H16>=96.5,H16<97),H16,ROUND(H16,0)) -> 75 | J16: =IF(I16<65,IF(I16<55,IF(I16<52,IF(I16<50,"F","D-"),"D"),IF(I16<57,"D+",IF(I16<60,"C-","C"))),IF(I16<75,IF(I16<70,"C+","B-"),IF(I16<85,IF(I16<80,"B","B+"),IF(I16<90,"A-",IF(I16<97,"A","A+"))))) -> B
A17: =A16+1 -> 10 | B17: 24201116 | C17: Zarif Tausif Ahmed Nafi | D17: ='Quiz Marks'!M15 -> 13.333333 | E17: 24 | F17: ='Mid Marks'!I15 -> 16.666667 | G17: ='Final Marks'!I15 -> 26 | H17: =SUM(D17:G17) -> 80 | I17: =IF(AND(H17>=96.5,H17<97),H17,ROUND(H17,0)) -> 80 | J17: =IF(I17<65,IF(I17<55,IF(I17<52,IF(I17<50,"F","D-"),"D"),IF(I17<57,"D+",IF(I17<60,"C-","C"))),IF(I17<75,IF(I17<70,"C+","B-"),IF(I17<85,IF(I17<80,"B","B+"),IF(I17<90,"A-",IF(I17<97,"A","A+"))))) -> B+
A18: =A17+1 -> 11 | B18: 22101447 | C18: Showrav Sutradhar | D18: ='Quiz Marks'!M16 -> 1 | E18: 0 | F18: ='Mid Marks'!I16 -> 8.3333333 | G18: ='Final Marks'!I16 -> 0 | H18: =SUM(D18:G18) -> 9.3333333 | I18: =IF(AND(H18>=96.5,H18<97),H18,ROUND(H18,0)) -> 9 | J18: =IF(I18<65,IF(I18<55,IF(I18<52,IF(I18<50,"F","D-"),"D"),IF(I18<57,"D+",IF(I18<60,"C-","C"))),IF(I18<75,IF(I18<70,"C+","B-"),IF(I18<85,IF(I18<80,"B","B+"),IF(I18<90,"A-",IF(I18<97,"A","A+"))))) -> F
A19: =A18+1 -> 12 | B19: 22201450 | C19: Mamduha Akter | D19: ='Quiz Marks'!M17 -> 10.916667 | E19: 17.1 | F19: ='Mid Marks'!I17 -> 10 | G19: ='Final Marks'!I17 -> 17 | H19: =SUM(D19:G19) -> 55.016667 | I19: =IF(AND(H19>=96.5,H19<97),H19,ROUND(H19,0)) -> 55 | J19: =IF(I19<65,IF(I19<55,IF(I19<52,IF(I19<50,"F","D-"),"D"),IF(I19<57,"D+",IF(I19<60,"C-","C"))),IF(I19<75,IF(I19<70,"C+","B-"),IF(I19<85,IF(I19<80,"B","B+"),IF(I19<90,"A-",IF(I19<97,"A","A+"))))) -> D+
A20: =A19+1 -> 13 | B20: 23301249 | C20: Md. Rafsan Elahi | D20: ='Quiz Marks'!M18 -> 12.166667 | E20: 16 | F20: ='Mid Marks'!I18 -> 10.833333 | G20: ='Final Marks'!I18 -> 21 | H20: =SUM(D20:G20) -> 60 | I20: =IF(AND(H20>=96.5,H20<97),H20,ROUND(H20,0)) -> 60 | J20: =IF(I20<65,IF(I20<55,IF(I20<52,IF(I20<50,"F","D-"),"D"),IF(I20<57,"D+",IF(I20<60,"C-","C"))),IF(I20<75,IF(I20<70,"C+","B-"),IF(I20<85,IF(I20<80,"B","B+"),IF(I20<90,"A-",IF(I20<97,"A","A+"))))) -> C
... A26: =A25+1 -> 19 | B26: 24201366 | C26: Lamiea Amzad Suhana | D26: ='Quiz Marks'!M24 -> 11.916667 | E26: 19.6 | F26: ='Mid Marks'!I24 -> 9.1666667 | G26: ='Final Marks'!I24 -> 14 | H26: =SUM(D26:G26) -> 54.683333 | I26: =IF(AND(H26>=96.5,H26<97),H26,ROUND(H26,0)) -> 55 | J26: =IF(I26<65,IF(I26<55,IF(I26<52,IF(I26<50,"F","D-"),"D"),IF(I26<57,"D+",IF(I26<60,"C-","C"))),IF(I26<75,IF(I26<70,"C+","B-"),IF(I26<85,IF(I26<80,"B","B+"),IF(I26<90,"A-",IF(I26<97,"A","A+"))))) -> D+
A27: =A26+1 -> 20 | B27: =B26+1 -> 24201367 | C27: Faria Fannana Toree | D27: ='Quiz Marks'!M25 -> 12.916667 | E27: 16.5 | F27: ='Mid Marks'!I25 -> 16.666667 | G27: ='Final Marks'!I25 -> 24 | H27: =SUM(D27:G27) -> 70.083333 | I27: =IF(AND(H27>=96.5,H27<97),H27,ROUND(H27,0)) -> 70 | J27: =IF(I27<65,IF(I27<55,IF(I27<52,IF(I27<50,"F","D-"),"D"),IF(I27<57,"D+",IF(I27<60,"C-","C"))),IF(I27<75,IF(I27<70,"C+","B-"),IF(I27<85,IF(I27<80,"B","B+"),IF(I27<90,"A-",IF(I27<97,"A","A+"))))) -> B-
A28: =A27+1 -> 21 | B28: 1000054019 | C28: Md. Abrarul Haque Pathan | D28: ='Quiz Marks'!M26 -> 11.083333 | E28: 20.8 | F28: ='Mid Marks'!I26 -> 15 | G28: ='Final Marks'!I26 -> 18 | H28: =SUM(D28:G28) -> 64.883333 | I28: =IF(AND(H28>=96.5,H28<97),H28,ROUND(H28,0)) -> 65 | J28: =IF(I28<65,IF(I28<55,IF(I28<52,IF(I28<50,"F","D-"),"D"),IF(I28<57,"D+",IF(I28<60,"C-","C"))),IF(I28<75,IF(I28<70,"C+","B-"),IF(I28<85,IF(I28<80,"B","B+"),IF(I28<90,"A-",IF(I28<97,"A","A+"))))) -> C+
A29: =A28+1 -> 22 | B29: 1000054082 | C29: Kamruzzaman Chowdhury | D29: ='Quiz Marks'!M27 -> 11.75 | E29: 25 | F29: ='Mid Marks'!I27 -> 21.666667 | G29: ='Final Marks'!I27 -> 27 | H29: =SUM(D29:G29) -> 85.416667 | I29: =IF(AND(H29>=96.5,H29<97),H29,ROUND(H29,0)) -> 85 | J29: =IF(I29<65,IF(I29<55,IF(I29<52,IF(I29<50,"F","D-"),"D"),IF(I29<57,"D+",IF(I29<60,"C-","C"))),IF(I29<75,IF(I29<70,"C+","B-"),IF(I29<85,IF(I29<80,"B","B+"),IF(I29<90,"A-",IF(I29<97,"A","A+"))))) -> A-
A30: =A29+1 -> 23 | B30: 1000054210 | C30: Adnan Tazbir Arian | D30: ='Quiz Marks'!M28 -> 8.6666667 | E30: 22.9 | F30: ='Mid Marks'!I28 -> 14.166667 | G30: ='Final Marks'!I28 -> 24 | H30: =SUM(D30:G30) -> 69.733333 | I30: =IF(AND(H30>=96.5,H30<97),H30,ROUND(H30,0)) -> 70 | J30: =IF(I30<65,IF(I30<55,IF(I30<52,IF(I30<50,"F","D-"),"D"),IF(I30<57,"D+",IF(I30<60,"C-","C"))),IF(I30<75,IF(I30<70,"C+","B-"),IF(I30<85,IF(I30<80,"B","B+"),IF(I30<90,"A-",IF(I30<97,"A","A+"))))) -> B-
A31: =A30+1 -> 24 | B31: 1000054898 | C31: Ryan Amin | D31: ='Quiz Marks'!M29 -> 14.166667 | E31: 23.9 | F31: ='Mid Marks'!I29 -> 16.666667 | G31: ='Final Marks'!I29 -> 15 | H31: =SUM(D31:G31)+23.9 -> 69.733333 | I31: =IF(AND(H31>=96.5,H31<97),H31,ROUND(H31,0)) -> 70 | J31: =IF(I31<65,IF(I31<55,IF(I31<52,IF(I31<50,"F","D-"),"D"),IF(I31<57,"D+",IF(I31<60,"C-","C"))),IF(I31<75,IF(I31<70,"C+","B-"),IF(I31<85,IF(I31<80,"B","B+"),IF(I31<90,"A-",IF(I31<97,"A","A+"))))) -> B-
A32: =A31+1 -> 25 | B32: 1000054905 | C32: Md. Yasin Islam Khan | D32: ='Quiz Marks'!M30 -> 10 | E32: 22.3 | F32: ='Mid Marks'!I30 -> 17.5 | G32: ='Final Marks'!I30 -> 15 | H32: =SUM(D32:G32) -> 64.8 | I32: =IF(AND(H32>=96.5,H32<97),H32,ROUND(H32,0)) -> 65 | J32: =IF(I32<65,IF(I32<55,IF(I32<52,IF(I32<50,"F","D-"),"D"),IF(I32<57,"D+",IF(I32<60,"C-","C"))),IF(I32<75,IF(I32<70,"C+","B-"),IF(I32<85,IF(I32<80,"B","B+"),IF(I32<90,"A-",IF(I32<97,"A","A+"))))) -> C+
A33: =A32+1 -> 26 | B33: 1000055328 | C33: Mos. Tawhida Rahman Tasfia | D33: ='Quiz Marks'!M31 -> 13.666667 | E33: 24.2 | F33: ='Mid Marks'!I31 -> 20 | G33: ='Final Marks'!I31 -> 27 | H33: =SUM(D33:G33) -> 84.866667 | I33: =IF(AND(H33>=96.5,H33<97),H33,ROUND(H33,0)) -> 85 | J33: =IF(I33<65,IF(I33<55,IF(I33<52,IF(I33<50,"F","D-"),"D"),IF(I33<57,"D+",IF(I33<60,"C-","C"))),IF(I33<75,IF(I33<70,"C+","B-"),IF(I33<85,IF(I33<80,"B","B+"),IF(I33<90,"A-",IF(I33<97,"A","A+"))))) -> A-
A34: =A33+1 -> 27 | B34: 1000055346 | C34: Emranul Haq Atonu | D34: ='Quiz Marks'!M32 -> 10 | E34: 23.8 | F34: ='Mid Marks'!I32 -> 20 | G34: ='Final Marks'!I32 -> 26 | H34: =SUM(D34:G34) -> 79.8 | I34: =IF(AND(H34>=96.5,H34<97),H34,ROUND(H34,0)) -> 80 | J34: =IF(I34<65,IF(I34<55,IF(I34<52,IF(I34<50,"F","D-"),"D"),IF(I34<57,"D+",IF(I34<60,"C-","C"))),IF(I34<75,IF(I34<70,"C+","B-"),IF(I34<85,IF(I34<80,"B","B+"),IF(I34<90,"A-",IF(I34<97,"A","A+"))))) -> B+
A35: =A34+1 -> 28 | B35: 1000055421 | C35: Nazia Tabassum Nawmee | D35: ='Quiz Marks'!M33 -> 14 | E35: 20.6 | F35: ='Mid Marks'!I33 -> 14.166667 | G35: ='Final Marks'!I33 -> 21 | H35: =SUM(D35:G35) -> 69.766667 | I35: =IF(AND(H35>=96.5,H35<97),H35,ROUND(H35,0)) -> 70 | J35: =IF(I35<65,IF(I35<55,IF(I35<52,IF(I35<50,"F","D-"),"D"),IF(I35<57,"D+",IF(I35<60,"C-","C"))),IF(I35<75,IF(I35<70,"C+","B-"),IF(I35<85,IF(I35<80,"B","B+"),IF(I35<90,"A-",IF(I35<97,"A","A+"))))) -> B-
A36: =A35+1 -> 29 | B36: 23101383 | C36: Raduan Rahman Ridoy | D36: ='Quiz Marks'!M34 -> 12.5 | E36: 15.7 | F36: ='Mid Marks'!I34 -> 17.5 | G36: ='Final Marks'!I34 -> 24 | H36: =SUM(D36:G36) -> 69.7 | I36: =IF(AND(H36>=96.5,H36<97),H36,ROUND(H36,0)) -> 70 | J36: =IF(I36<65,IF(I36<55,IF(I36<52,IF(I36<50,"F","D-"),"D"),IF(I36<57,"D+",IF(I36<60,"C-","C"))),IF(I36<75,IF(I36<70,"C+","B-"),IF(I36<85,IF(I36<80,"B","B+"),IF(I36<90,"A-",IF(I36<97,"A","A+"))))) -> B-
A37: =A36+1 -> 30 | B37: 24121350 | C37: Md.Fahim Muntasir | D37: ='Quiz Marks'!M35 -> 0 | E37: 2 | F37: ='Mid Marks'!I35 -> 13.333333 | G37: ='Final Marks'!I35 -> 0 | H37: =SUM(D37:G37) -> 15.333333 | I37: =IF(AND(H37>=96.5,H37<97),H37,ROUND(H37,0)) -> 15 | J37: =IF(I37<65,IF(I37<55,IF(I37<52,IF(I37<50,"F","D-"),"D"),IF(I37<57,"D+",IF(I37<60,"C-","C"))),IF(I37<75,IF(I37<70,"C+","B-"),IF(I37<85,IF(I37<80,"B","B+"),IF(I37<90,"A-",IF(I37<97,"A","A+"))))) -> F
A38: =A37+1 -> 31 | B38: 1000058970 | C38: Amitrakshar Biswas | D38: ='Quiz Marks'!M36 -> 14.666667 | E38: 25 | F38: ='Mid Marks'!I36 -> 25 | G38: ='Final Marks'!I36 -> 35 | H38: =SUM(D38:G38) -> 99.666667 | I38: =IF(AND(H38>=96.5,H38<97),H38,ROUND(H38,0)) -> 100 | J38: =IF(I38<65,IF(I38<55,IF(I38<52,IF(I38<50,"F","D-"),"D"),IF(I38<57,"D+",IF(I38<60,"C-","C"))),IF(I38<75,IF(I38<70,"C+","B-"),IF(I38<85,IF(I38<80,"B","B+"),IF(I38<90,"A-",IF(I38<97,"A","A+"))))) -> A+
A39: =A38+1 -> 32 | B39: 24321209 | C39: Subhaha Israth Jahaan | D39: ='Quiz Marks'!M37 -> 10.083333 | E39: 22.3 | F39: ='Mid Marks'!I37 -> 15.833333 | G39: ='Final Marks'!I37 -> 22 | H39: =SUM(D39:G39) -> 70.216667 | I39: =IF(AND(H39>=96.5,H39<97),H39,ROUND(H39,0)) -> 70 | J39: =IF(I39<65,IF(I39<55,IF(I39<52,IF(I39<50,"F","D-"),"D"),IF(I39<57,"D+",IF(I39<60,"C-","C"))),IF(I39<75,IF(I39<70,"C+","B-"),IF(I39<85,IF(I39<80,"B","B+"),IF(I39<90,"A-",IF(I39<97,"A","A+"))))) -> B-
A40: =A39+1 -> 33 | B40: 24121314 | C40: Mostofa Galib | D40: ='Quiz Marks'!M38 -> 0 | E40: 0 | F40: ='Mid Marks'!I38 -> 0 | G40: ='Final Marks'!I38 -> 0 | H40: =SUM(D40:G40) -> 0 | I40: =IF(AND(H40>=96.5,H40<97),H40,ROUND(H40,0)) -> 0 | J40: =IF(I40<65,IF(I40<55,IF(I40<52,IF(I40<50,"F","D-"),"D"),IF(I40<57,"D+",IF(I40<60,"C-","C"))),IF(I40<75,IF(I40<70,"C+","B-"),IF(I40<85,IF(I40<80,"B","B+"),IF(I40<90,"A-",IF(I40<97,"A","A+"))))) -> F
A41: =A40+1 -> 34 | B41: 24101166 | C41: Tahsin Ahmed | D41: ='Quiz Marks'!M39 -> 2.75 | E41: 0 | F41: ='Mid Marks'!I39 -> 9.1666667 | G41: ='Final Marks'!I39 -> 0 | H41: =SUM(D41:G41) -> 11.916667 | I41: =IF(AND(H41>=96.5,H41<97),H41,ROUND(H41,0)) -> 12 | J41: =IF(I41<65,IF(I41<55,IF(I41<52,IF(I41<50,"F","D-"),"D"),IF(I41<57,"D+",IF(I41<60,"C-","C"))),IF(I41<75,IF(I41<70,"C+","B-"),IF(I41<85,IF(I41<80,"B","B+"),IF(I41<90,"A-",IF(I41<97,"A","A+"))))) -> F
A42: =A41+1 -> 35 | B42: 24321189 | C42: A K M Amirul Muminin Sadi | D42: ='Quiz Marks'!M40 -> 9 | E42: 20.1 | F42: ='Mid Marks'!I40 -> 15.833333 | G42: ='Final Marks'!I40 -> 21 | H42: =SUM(D42:G42) -> 65.933333 | I42: =IF(AND(H42>=96.5,H42<97),H42,ROUND(H42,0)) -> 66 | J42: =IF(I42<65,IF(I42<55,IF(I42<52,IF(I42<50,"F","D-"),"D"),IF(I42<57,"D+",IF(I42<60,"C-","C"))),IF(I42<75,IF(I42<70,"C+","B-"),IF(I42<85,IF(I42<80,"B","B+"),IF(I42<90,"A-",IF(I42<97,"A","A+"))))) -> C+
A43: =A42+1 -> 36 | B43: 23301466 | C43: Shadman Sakib | D43: ='Quiz Marks'!M41 -> 10.75 | E43: 19.2 | F43: ='Mid Marks'!I41 -> 15 | G43: ='Final Marks'!I41 -> 25 | H43: =SUM(D43:G43) -> 69.95 | I43: =IF(AND(H43>=96.5,H43<97),H43,ROUND(H43,0)) -> 70 | J43: =IF(I43<65,IF(I43<55,IF(I43<52,IF(I43<50,"F","D-"),"D"),IF(I43<57,"D+",IF(I43<60,"C-","C"))),IF(I43<75,IF(I43<70,"C+","B-"),IF(I43<85,IF(I43<80,"B","B+"),IF(I43<90,"A-",IF(I43<97,"A","A+"))))) -> B-
... A47: =A46+1 -> 40 | B47: 24321192 | C47: Shadman Ahmed | D47: ='Quiz Marks'!M45 -> 8.75 | E47: 21.7 | F47: ='Mid Marks'!I45 -> 14.166667 | G47: ='Final Marks'!I45 -> 25 | H47: =SUM(D47:G47) -> 69.616667 | I47: =IF(AND(H47>=96.5,H47<97),H47,ROUND(H47,0)) -> 70 | J47: =IF(I47<65,IF(I47<55,IF(I47<52,IF(I47<50,"F","D-"),"D"),IF(I47<57,"D+",IF(I47<60,"C-","C"))),IF(I47<75,IF(I47<70,"C+","B-"),IF(I47<85,IF(I47<80,"B","B+"),IF(I47<90,"A-",IF(I47<97,"A","A+"))))) -> B-
